<mujoco model="arena">
  <compiler angle="radian"/>
  <asset>
    <texture type="skybox" builtin="flat"  width="1" height="1" rgb1="1 1 1" rgb2="1 1 1" />
    <texture name='groundplane' type='2d' builtin='checker' rgb1='.2 .3 .4' rgb2='.1 .2 .3' width='300' height='300' mark='edge' markrgb='.8 .8 .8'/>
    <material name='groundplane' texture='groundplane' texrepeat='5 5' texuniform='true' reflectance='.2'/>
  </asset>

  <worldbody>
    <site name="left" pos="0 0.205 0.5" quat="0.5 -0.5  0.5 -0.5" />
    <site name="right" pos="0 -0.205 0.5" quat="0.5 0.5 0.5 0.5" />
    <light directional='true' diffuse='.7 .7 .7' pos='1 .1 2' dir='0 -.1 -2' specular='.3 .3 .3' castshadow='true'/>
    <body pos="1 0 .3" mocap="true" name="plane">
      <geom name="plane" type="box" size=".2 .4 .01" />
      <body pos="0 0 .06" name="object">
        <joint name="x" type="slide" axis="1 0 0" range="-.2 .2" />
        <joint name="y" type="slide" axis="0 1 0" range="-.4 .4" />
        <joint name="theta" type="hinge" axis="0 0 1" />
        <geom name="object" type="box" size=".05 .05 .05"  rgba="1 0 0 1" />
      </body>
    </body>
  </worldbody>
</mujoco>
