<mujoco model="arena">
  <compiler angle="radian"/>
  <asset>
    <texture type="skybox" builtin="flat"  width="1" height="1" rgb1="1 1 1" rgb2="1 1 1" />
    <texture name='groundplane' type='2d' builtin='checker' rgb1='.2 .3 .4' rgb2='.1 .2 .3' width='300' height='300' mark='edge' markrgb='.8 .8 .8'/>
    <material name='groundplane' texture='groundplane' texrepeat='5 5' texuniform='true' reflectance='.2'/>
  </asset>

  <worldbody>
    <site name="left" pos="0 0.24 0.5" quat="0.5 -0.5  0.5 -0.5" />
    <site name="right" pos="0 -0.24 0.5" quat="0.5 0.5 0.5 0.5" />
    <light directional='true' diffuse='.7 .7 .7' pos='1 .1 2' dir='0 -.1 -2' specular='.3 .3 .3' castshadow='true'/>
    <body pos=".845 0.012 .34" name="plane">
      <geom name="plane" type="box" pos="0 0 -.01" size=".1 .2 .01" rgba=".2 .2 .2 1" />
      <body><body>
      <geom name="side_a" type="box" pos=".0985 0 .005" size=".0015 .2 .005" rgba=".2 .2 .2 1" />
      <geom name="side_b" type="box" pos="-.0985 0 .005" size=".0015 .2 .005" rgba=".2 .2 .2 1" />
      <geom name="side_c" type="box" pos="0 .1985 .005" size=".097 .0015 .005" rgba=".2 .2 .2 1" />
      <geom name="side_d" type="box" pos="0 -.1985 .005" size=".097 .0015 .005" rgba=".2 .2 .2 1" />
      </body></body>
      <joint name="plane" type="hinge" axis="1 0 0" range="-0.2617 0.2617" />
      <body name="object">
        <joint name="x" type="slide" axis="1 0 0" />
        <joint name="y" type="slide" axis="0 1 0" />
        <joint name="theta" type="hinge" axis="0 0 1" />
        <geom type="box" name="object_1" size=".015 .04 .015" pos="0.015 -0.04 0.015" rgba=".8 .8 .8 1" />
        <geom type="box" name="object_2" size=".06 .015 .015" pos=".09 -.065 0.015" rgba=".8 .8 .8 1" />
      </body>
    </body>
  </worldbody>
  <contact>
    <pair geom1="object_1" geom2="side_a" />
    <pair geom1="object_1" geom2="side_b" />
    <pair geom1="object_1" geom2="side_c" />
    <pair geom1="object_1" geom2="side_d" />
    <pair geom1="object_2" geom2="side_a" />
    <pair geom1="object_2" geom2="side_b" />
    <pair geom1="object_2" geom2="side_c" />
    <pair geom1="object_2" geom2="side_d" />
  </contact>
</mujoco>
